DEBUG:websockets.client:= connection is CONNECTING
DEBUG:websockets.client:> GET /v1/speak?encoding=linear16&sample_rate=24000&&model=aura-stella-en HTTP/1.1
DEBUG:websockets.client:> Host: api.deepgram.com
DEBUG:websockets.client:> Upgrade: websocket
DEBUG:websockets.client:> Connection: Upgrade
DEBUG:websockets.client:> Sec-WebSocket-Key: H6nl7A1oKpaVTzq1lI19Gw==
DEBUG:websockets.client:> Sec-WebSocket-Version: 13
DEBUG:websockets.client:> Sec-WebSocket-Extensions: permessage-deflate; client_max_window_bits
DEBUG:websockets.client:> Authorization: Token ...
DEBUG:websockets.client:> User-Agent: Python/3.13 websockets/12.0
DEBUG:websockets.client:< HTTP/1.1 401 Unauthorized
DEBUG:websockets.client:< content-type: application/json
DEBUG:websockets.client:< dg-error: Invalid credentials.
DEBUG:websockets.client:< vary: origin, access-control-request-method, access-control-request-headers
DEBUG:websockets.client:< vary: accept-encoding
DEBUG:websockets.client:< access-control-allow-credentials: true
DEBUG:websockets.client:< access-control-expose-headers: dg-model-name,dg-model-uuid,dg-char-count,dg-request-id,dg-error
DEBUG:websockets.client:< dg-request-id: 433d6eb8-ae8c-454b-ba61-1e897b2ca0f9
DEBUG:websockets.client:< content-length: 112
DEBUG:websockets.client:< date: Sun, 16 Feb 2025 23:35:21 GMT
DEBUG:websockets.client:< [body] (112 bytes)
DEBUG:websockets.client:< EOF
DEBUG:websockets.client:> EOF
DEBUG:websockets.client:= connection is CLOSED
ERROR:asyncio:Task exception was never retrieved
future: <Task finished name='Task-3' coro=<destroy() done, defined at /Users/user/Desktop/fix/main.py:78> exception=NameError("name 'interviewer' is not defined")>
Traceback (most recent call last):
  File "/Users/user/Desktop/fix/main.py", line 106, in <module>
    loop.run_forever()
    ~~~~~~~~~~~~~~~~^^
  File "/opt/homebrew/Cellar/python@3.13/3.13.1/Frameworks/Python.framework/Versions/3.13/lib/python3.13/asyncio/base_events.py", line 678, in run_forever
    self._run_once()
    ~~~~~~~~~~~~~~^^
  File "/opt/homebrew/Cellar/python@3.13/3.13.1/Frameworks/Python.framework/Versions/3.13/lib/python3.13/asyncio/base_events.py", line 1995, in _run_once
    event_list = self._selector.select(timeout)
  File "/opt/homebrew/Cellar/python@3.13/3.13.1/Frameworks/Python.framework/Versions/3.13/lib/python3.13/selectors.py", line 548, in select
    kev_list = self._selector.control(None, max_ev, timeout)
  File "/Users/user/Desktop/fix/main.py", line 93, in sigterm_handler
    loop.close()
    ~~~~~~~~~~^^
  File "/opt/homebrew/Cellar/python@3.13/3.13.1/Frameworks/Python.framework/Versions/3.13/lib/python3.13/asyncio/unix_events.py", line 70, in close
    super().close()
    ~~~~~~~~~~~~~^^
  File "/opt/homebrew/Cellar/python@3.13/3.13.1/Frameworks/Python.framework/Versions/3.13/lib/python3.13/asyncio/selector_events.py", line 101, in close
    raise RuntimeError("Cannot close a running event loop")
RuntimeError: Cannot close a running event loop

During handling of the above exception, another exception occurred:

Traceback (most recent call last):
  File "/Users/user/Desktop/fix/main.py", line 83, in destroy
    if interviewer != None and not stopped:
       ^^^^^^^^^^^
NameError: name 'interviewer' is not defined. Did you mean: 'AIInterviewer'?
